Workbook

Sheet Siwei
A1: 工作内容（大类） | B1: 工作内容 | C1: 平均花费时间 | D1: Day | E1: Weekly | F1: Monthly | G1: 42446 | H1: 42447 | I1: 42450 | J1: 42451 | K1: 42452 | L1: 42453 | M1: 42454 | N1: 42455 | O1: 42456 | P1: 42457
A2: QG 管理 | B2: QG PID | C2: =D2+E2/5+F2/22 -> 20 | D2: 20 | G2: √ | H2: √ | I2: √ | J2: √ | K2: √ | L2: √ | M2: √
B3: QG办公室5s整理 | C3: =D3+E3/5+F3/22 -> 10 | D3: 10 | G3: √
B4: 标准化、5s审核 | C4: =D4+E4/5+F4/22 -> 2.7272727 | F4: 60
B5: QG smart goal update | C5: =D5+E5/5+F5/22 -> 2.7272727 | F5: 60
B6: BIQ展板更新 | C6: =D6+E6/5+F6/22 -> 2 | E6: 10
B7: 培训录入 | C7: =D7+E7/5+F7/22 -> 6 | E7: 30
B8: CI卡录入 | C8: =D8+E8/5+F8/22 -> 5 | D8: 5
B9: Weekly Focus | C9: =D9+E9/5+F9/22 -> 12 | E9: 60
A10: 内部质量 | B10: 现场巡查 | C10: =D10+E10/5+F10/22 -> 60 | D10: 60
B11: 现场质量判定 | C11: =D11+E11/5+F11/22 -> 69 | D11: 69
B12: 三坐标测量机维护 | C12: =D12+E12/5+F12/22 -> 6 | E12: 30
B13: 与ATL信息交流 | C13: =D13+E13/5+F13/22 -> 2.7272727 | F13: 60
B14: 质量行走 | C14: =D14+E14/5+F14/22 -> 40 | D14: 40
B15: 内审 | C15: =D15+E15/5+F15/22 -> 2.7272727 | F15: 60
B16: PID | C16: =D16+E16/5+F16/22 -> 60 | D16: 60
B17: Gap analysis update | C17: =D17+E17/5+F17/22 -> 1.3636364 | F17: 30
B18: Gap analysis audit | C18: =D18+E18/5+F18/22 -> 6 | E18: 30
B19: 部门间会议交流 | C19: =D19+E19/5+F19/22 -> 60 | D19: 60
A20: QS（部门内交流） | B20: Quality staff meeting | C20: =D20+E20/5+F20/22 -> 12 | E20: 60
B21: Quality improvement discuss | C21: =D21+E21/5+F21/22 -> 12 | E21: 60
B22: 持续改进 | C22: =D22+E22/5+F22/22 -> 2.7272727 | F22: 60
A23: 数据报告 | B23: 公司级BIQ data | C23: =D23+E23/5+F23/22 -> 8.1818182 | F23: 180 | G23: √ | H23: √ | I23: √ | J23: √ | K23: √ | L23: √
B24: 公司级BIQ Offender Chart | C24: =D24+E24/5+F24/22 -> 0.90909091 | F24: 20
B25: TG Rework Record | C25: =D25+E25/5+F25/22 -> 0.45454545 | F25: 10
B26: PDI defect free | C26: =D26+E26/5+F26/22 -> 0.45454545 | F26: 10
B27: IQA Record | C27: =D27+E27/5+F27/22 -> 1.3636364 | F27: 30
B28: Scrap | C28: =D28+E28/5+F28/22 -> 0.90909091 | F28: 20
B29: TCOQ | C29: =D29+E29/5+F29/22 -> 1.8181818 | F29: 40
B30: Delivery PPM Record | C30: =D30+E30/5+F30/22 -> 0.45454545 | F30: 10
B31: CUXL Quality Dashboard | C31: =D31+E31/5+F31/22 -> 2.7272727 | F31: 60
B32: VSC | C32: =D32+E32/5+F32/22 -> 5.4545455 | F32: 120
B33: CUXL OQL | C33: =D33+E33/5+F33/22 -> 0.90909091 | F33: 20
B34: CUXL 质量数据汇总 | C34: =D34+E34/5+F34/22 -> 7.2727273 | F34: 160
B35: Bi-Weekly report | C35: =D35+E35/5+F35/22 -> 6 | E35: 30
B36: 厂级PID数据更新 | C36: =D36+E36/5+F36/22 -> 2.7272727 | F36: 60
A37: BIQ | B37: BIQ workshop | C37: =D37+E37/5+F37/22 -> 21.818182 | F37: 480
B38: QA & 8D weekly review meeting | C38: =D38+E38/5+F38/22 -> 18 | E38: 90
B39: 小计 | C39: =SUM(C2:C37) -> 456.45455 | D39: =SUM(D2:D37) -> 324 | E39: =SUM(E2:E37) -> 310 | F39: =SUM(F2:F37) -> 1550 | G39: =SUM(G2:G37) -> 0 | H39: =SUM(H2:H37) -> 0 | I39: =SUM(I2:I37) -> 0 | J39: =SUM(J2:J37) -> 0 | ... P39: =SUM(P2:P37) -> 0
A40: 总计 | B40: QG 管理 | C40: =SUM(C2:C9) -> 60.454545
...

Sheet Sheet3
A1: 2016年4月份白班(Day 1-Day 7) | E1: 2016年4月份夜班(Day 1-Day 7) | I1: 2016年4月份白班(Day 8-Day 19) | M1: 2016年4月份夜班(Day 8-Day 19) | Q1: 2016年4月份白班(Day 20-Day 25) | U1: 2016年4月份夜班(Day 20-Day 25)
A2: 工作区域 | B2: 开线的条数 | C2: 所需时间 | D2: 所需人数 | E2: 工作区域 | F2: 开线的条数 | G2: 所需时间 | H2: 所需人数 | I2: 工作区域 | J2: 开线的条数 | K2: 所需时间 | L2: 所需人数 | M2: 工作区域 | N2: 开线的条数 | O2: 所需时间 | P2: 所需人数 | Q2: 工作区域 | R2: 开线的条数 | S2: 所需时间 | T2: 所需人数 | U2: 工作区域 | V2: 开线的条数 | W2: 所需时间 | X2: 所需人数
A3: PB-HT | B3: 3 | C3: =QG!$E4 -> 113 | D3: =((B3*C3+B4*C4+B5*C5+B6*C6+B7*C7)-30-2*50)/440 -> 1.5511364 | E3: PB-HT | F3: 4 | G3: =QG!E4 -> 113 | H3: =((F3*G3+F4*G4+F5*G5+F6*G6+F7*G7)-30-2*50)/440 -> 1.5136364 | I3: PB-HT | J3: 4 | K3: =QG!$E4 -> 113 | L3: =((J3*K3+J4*K4+J5*K5+J6*K6+J7*K7)-30-2*50)/440 -> 2.0272727 | M3: PB-HT | N3: 4 | O3: =QG!$E4 -> 113 | P3: =((N3*O3+N4*O4+N5*O5+N6*O6+N7*O7)-30-2*50)/440 -> 1.5136364 | Q3: PB-HT | R3: 3 | S3: =QG!$E4 -> 113 | T3: =((R3*S3+R4*S4+R5*S5+R6*S6+R7*S7)-6*30)/440 -> 1.4375 | U3: PB-HT | V3: 4 | W3: =QG!$E4 -> 113 | X3: =((V3*W3+V4*W4+V5*W5+V6*W6+V7*W7)-6*30)/440 -> 1.2113636
A4: Link-HT | B4: 3 | C4: =QG!$E5 -> 40.5 | E4: Link-HT | F4: 2 | G4: =QG!E6 -> 10 | I4: Link-HT | J4: 3 | K4: =QG!$E6 -> 10 | M4: Link-HT | N4: 2 | O4: =QG!$E6 -> 10 | Q4: Link-HT | R4: 3 | S4: =QG!$E5 -> 40.5 | U4: Link-HT | V4: 2 | W4: =QG!$E5 -> 40.5
A5: Link-M | B5: 3 | C5: =QG!$E6 -> 10 | E5: Link-M | F5: 2 | G5: =QG!E7 -> 80 | I5: Link-M | J5: 3 | K5: =QG!$E7 -> 80 | M5: Link-M | N5: 2 | O5: =QG!$E7 -> 80 | Q5: Link-M | R5: 3 | S5: =QG!$E6 -> 10 | U5: Link-M | V5: 2 | W5: =QG!$E6 -> 10
A6: Ass | B6: 3 | C6: =QG!$E7 -> 80 | E6: Ass | F6: 2 | G6: =QG!E8 -> 82 | I6: Ass | J6: 3 | K6: =QG!$E8 -> 82 | M6: Ass | N6: 2 | O6: =QG!$E8 -> 82 | Q6: Ass | R6: 3 | S6: =QG!$E7 -> 80 | U6: Ass | V6: 2 | W6: =QG!$E7 -> 80
A7: Roller | B7: 1 | C7: =QG!$E8 -> 82 | E7: Roller | F7: 0 | G7: =QG!E9 -> 54 | I7: Roller | J7: 1 | K7: =QG!$E9 -> 54 | M7: Roller | N7: 0 | O7: =QG!$E9 -> 54 | Q7: Roller | R7: 1 | S7: =QG!$E8 -> 82 | U7: Roller | V7: 0 | W7: =QG!$E8 -> 82
A8: Painting | B8: 1 | C8: =QG!$E9 -> 54 | E8: Painting | F8: 0 | G8: =QG!E10 -> 5 | I8: Painting | J8: 1 | K8: =QG!$E10 -> 5 | M8: Painting | N8: 0 | O8: =QG!$E10 -> 5 | Q8: Painting | R8: 1 | S8: =QG!$E9 -> 54 | U8: Painting | V8: 0 | W8: =QG!$E9 -> 54
A9: 备注：
A10: 销售件计划只有一个星期的提前期，因此19号以后的无法预测
A12: 2016年11月份白班 | F12: 2016年11月份夜班
A13: 工作区域 | B13: 开线的条数 | C13: 所需时间 | D13: 所需人数 | F13: 工作区域 | G13: 开线的条数 | H13: 所需时间 | I13: 所需人数
A14: PB-HT | B14: 4 | C14: =#REF! -> #REF! | D14: =((B14*C14+B15*C15+B16*C16+B17*C17+B18*C18)-30*2-3*50)/440 -> #REF! | F14: PB-HT | G14: 2 | H14: =#REF! -> #REF! | I14: =((G14*H14+G15*H15+G16*H16+G17*H17+G18*H18)-30*2-3*50)/440 -> #REF!
A15: Link-HT | B15: 4 | C15: =#REF! -> #REF! | F15: Link-HT | G15: 2 | H15: =#REF! -> #REF!
A16: Link-M | B16: 4 | C16: =#REF! -> #REF! | F16: Link-M | G16: 2 | H16: =#REF! -> #REF!
A17: Ass | B17: 4 | C17: =#REF! -> #REF! | F17: Ass | G17: 2 | H17: =#REF! -> #REF!
A18: Roller | B18: 1 | C18: =#REF! -> #REF! | F18: Roller | G18: 1 | H18: =#REF! -> #REF!
A19: Painting | B19: 1 | C19: =#REF! -> #REF! | F19: Painting | G19: 1 | H19: =#REF! -> #REF!
A21: 2016年11月份白班-2/3/Roller | F21: 2016年11月份白班-4/5/Painting
A22: 工作区域 | B22: 开线的条数 | C22: 所需时间 | D22: 所需人数 | F22: 工作区域 | G22: 开线的条数 | H22: 所需时间 | I22: 所需人数
A23: PB-HT | B23: 2 | C23: =#REF! -> #REF! | D23: =((B23*C23+B24*C24+B25*C25+B26*C26+B27*C27)-30*2-3*50)/440 -> #REF! | F23: PB-HT | G23: 2 | H23: =#REF! -> #REF! | I23: =((G23*H23+G24*H24+G25*H25+G26*H26+G27*H27)-30*2-3*50)/440 -> #REF!
A24: Link-HT | B24: 2 | C24: =#REF! -> #REF! | F24: Link-HT | G24: 2 | H24: =#REF! -> #REF!
A25: Link-M | B25: 2 | C25: =#REF! -> #REF! | F25: Link-M | G25: 2 | H25: =#REF! -> #REF!
A26: Ass | B26: 2 | C26: =#REF! -> #REF! | F26: Ass | G26: 2 | H26: =#REF! -> #REF!
A27: Roller | B27: 1 | C27: =#REF! -> #REF!
F28: Painting | G28: 1 | H28: =#REF! -> #REF!

Sheet QG
A1: QG工作内容时间表
A2: 工作内容 | B2: 区域 | C2: 零部件 | D2: 单条生产线工作内容 | E2: CT | F2: 频率 | G2: 白班每天所需时间 | H2: 夜班每天所需时间 | I2: 实际时间 | J2: 小时
A3: / | B3: 合计 | E3: =SUM(E4:E9) -> 379.5 | J3: =E3/60 -> 6.325
B4: PB-HT | E4: =SUM(G10:G11,G13:G14,G16:G20,G22:G23,G25:G26,G28:G29) -> 113 | J4: =E4/60 -> 1.8833333
B5: Link-H | E5: =SUM(G12,G15,G21,G24,G27,G30) -> 40.5 | J5: =E5/60 -> 0.675
B6: Link-M | E6: =G31 -> 10 | J6: =E6/60 -> 0.16666667
B7: ASS | E7: =SUM(G32:G34) -> 80 | J7: =E7/60 -> 1.3333333
B8: Roller | E8: =SUM(G35:G41) -> 82 | J8: =E8/60 -> 1.3666667
B9: Painting | E9: =SUM(G42:G43) -> 54 | J9: =E9/60 -> 0.9
A10: 开班 | B10: PBL热处理 | C10: Pin | D10: 开班送检Pin2pcs | E10: 5 | F10: 1 | G10: =F10*E10 -> 5 | H10: =E10*1 -> 5
C11: Bushing | D11: 开班送检Bushing2pcs | E11: 5 | F11: 1 | G11: =F11*E11 -> 5 | H11: =E11*1 -> 5
C12: Link | D12: 开班送检Link2pcs | E12: 5 | F12: 1 | G12: =F12*E12 -> 5 | H12: =E12*1 -> 5
A13: 工艺 | C13: Pin | D13: 工艺送检Pin2pcs | E13: 5 | F13: 1 | G13: =F13*E13 -> 5 | H13: =E13*2 -> 10
C14: Bushing | D14: 工艺送检Bushing2pcs | E14: 5 | F14: 1 | G14: =F14*E14 -> 5 | H14: =E14*2 -> 10
C15: Link | D15: 工艺送检Link2pcs | E15: 5 | F15: 1 | G15: =F15*E15 -> 5 | H15: =E15*1 -> 5
A16: 序间检测 | C16: Pin | D16: Pin的热处理尺寸检测/2pcs | E16: 2 | F16: 2 | G16: =F16*E16 -> 4 | H16: =E16*2 -> 4
C17: Pin | D17: Pin的毛坯尺寸检测/2pcs
C18: Bushing | D18: Bushing的热处理尺寸检测/2pcs | E18: 12 | F18: 2 | G18: =F18*E18 -> 24 | H18: =E18*2 -> 24
C19: Pin | D19: Pin的外观检测/6pcs | E19: 3 | F19: 2 | G19: =F19*E19 -> 6 | H19: =E19*6 -> 18
C20: Bushing | D20: Bushing的外观检测/6pcs | E20: 3 | F20: 2 | G20: =F20*E20 -> 6 | H20: =E20*2 -> 6
C21: Link | D21: Link的外观检测/4pcs | E21: 2 | F21: 2 | G21: =F21*E21 -> 4 | H21: =E21*3 -> 6
C22: Pin | D22: 磁粉探伤/2pcs | E22: 1.5 | F22: 3 | G22: =F22*E22 -> 4.5 | H22: =E22*3 -> 4.5
C23: Bushing | D23: 磁粉探伤/2pcs | E23: 1.5 | F23: 3 | G23: =F23*E23 -> 4.5 | H23: =E23*3 -> 4.5
C24: Link | D24: 磁粉探伤/2pcs | E24: 1.5 | F24: 3 | G24: =F24*E24 -> 4.5 | H24: =E24*3 -> 4.5
C25: Pin | D25: 表硬检测/2pcs | E25: 4 | F25: 3 | G25: =F25*E25 -> 12 | H25: =E25*3 -> 12
C26: Bushing | D26: 表硬检测/2pcs | E26: 4 | F26: 3 | G26: =F26*E26 -> 12 | H26: =E26*3 -> 12
C27: Link | D27: 表硬检测/2pcs | E27: 4 | F27: 3 | G27: =F27*E27 -> 12 | H27: =E27*3 -> 12
A28: 序间巡检 | C28: Pin-HT | D28: 待处理物料审核 | E28: 10 | F28: 1 | G28: =F28*E28 -> 10 | H28: =E28*1 -> 10
C29: Bushing-HT | D29: 待处理物料审核 | E29: 10 | F29: 1 | G29: =F29*E29 -> 10 | H29: =E29*1 -> 10
C30: Link-HT | D30: 待处理物料审核 | E30: 10 | F30: 1 | G30: =F30*E30 -> 10 | H30: =E30*1 -> 10
B31: Link-M | C31: Link-M | D31: 待处理物料审核 | E31: 10 | F31: 1 | G31: =F31*E31 -> 10 | H31: =E31*1 -> 10
B32: ASS | C32: ASS | D32: 待处理物料审核 | E32: 10 | F32: 1 | G32: =F32*E32 -> 10 | H32: =E32*1 -> 10
C33: ASS | D33: 开口/整齐度/板缝 | E33: 2 | F33: 10 | G33: =F33*E33 -> 20 | H33: =E33*10 -> 20
C34: ASS | D34: 外观检测 | E34: 5 | F34: 10 | G34: =F34*E34 -> 50 | H34: =E34*10 -> 50
A35: 序间检测 | B35: Roller | C35: Roller | D35: 清洁度送检 | E35: 5 | F35: 2 | G35: =F35*E35 -> 10
C36: Roller | D36: 密封圈高度 | E36: 1 | F36: 2 | G36: =F36*E36 -> 2
C37: Roller | D37: 轴承跨距 | E37: 2.5 | F37: 2 | G37: =F37*E37 -> 5
C38: Roller | D38: 窜动量 | E38: 2.5 | F38: 2 | G38: =F38*E38 -> 5
C39: Roller | D39: 零部件检测 | E39: 10 | F39: 2 | G39: =F39*E39 -> 20
A40: 序间巡检 | C40: Roller | D40: 待处理物料审核 | E40: 10 | F40: 2 | G40: =F40*E40 -> 20
...

Sheet 2025-1&2&3线
A1: 区域 | B1: 零部件 | C1: 生产线工作内容 | D1: 数量 | E1: CT/秒 | F1: 频次/班 | G1: 用时/秒 | H1: 备注
A2: PBL-HT | B2: Pin | C2: 表硬 | D2: 1对 | E2: 120 | F2: 6 | G2: =E2*F2 -> 720 | H2: 2线4次，3线2次
B3: Bushing | C3: 表硬 | D3: 1对 | E3: 120 | F3: 6 | G3: =E3*F3 -> 720 | H3: 2线4次，3线2次
B4: Link | C4: H-length检测；表硬（开班） | D4: 1对 | E4: 480 | F4: 3 | G4: =E4*F4 -> 1440 | H4: 1线1次，2线1次，3线1线
B5: Link | C5: H-length检测；表硬（快速） | D5: 1对 | E5: 480 | F5: 5 | G5: =E5*F5 -> 2400 | H5: 1线1次，2线3次，3线1线
B6: Pin（开班） | C6: 磁粉探伤 | D6: 1对 | E6: 60 | F6: 2 | G6: =E6*F6 -> 120 | H6: 2线1次，3线1次
B7: Bushing（开班） | D7: 1对 | E7: 60 | F7: 2 | G7: =E7*F7 -> 120 | H7: 2线1次，3线1次
B8: Bushing（每2小时） | D8: 2对 | E8: 120 | F8: 6 | G8: =E8*F8 -> 720 | H8: 2线3次，3线3次
B9: Link（开班） | D9: 1对 | E9: 60 | F9: 3 | G9: =E9*F9 -> 180 | H9: 1线1次，2线3次，3线1次
B10: Link（每2小时） | D10: 2对 | E10: 120 | F10: 9 | G10: =E10*F10 -> 1080 | H10: 1线3次，2线3次，3线3次
B11: Pin | C11: 热处理尺寸检测 | D11: 1对 | E11: 120 | F11: 5 | G11: =E11*F11 -> 600 | H11: 2线4次，3线1次
B12: Bushing | D12: 1对 | E12: 180 | F12: 4 | G12: =E12*F12 -> 720 | H12: 2线3次，3线1次
B13: Bushing（CMM） | D13: 1对 | E13: 720 | F13: 1 | G13: =E13*F13 -> 720 | H13: 2线1次
B14: Pin | C14: 外观目视检测 | D14: 10对 | E14: 100 | F14: 8 | G14: =E14*F14 -> 800 | H14: 销子销套链节各1线4次，2线4次，3线4线
B15: Bushing | D15: 10对 | E15: 100 | F15: 8 | G15: =E15*F15 -> 800
B16: Link | D16: 6对 | E16: 150 | F16: 12 | G16: =E16*F16 -> 1800
B17: Link | C17: 换型打磨时间 | D17: 1对 | E17: 300 | F17: 3 | G17: =E17*F17 -> 900
B18: Pin | C18: 磁粉探伤（换型MT） | D18: 1对 | E18: 60 | F18: 1 | G18: =E18*F18 -> 60
B19: Bushing | D19: 12对 | E19: 720 | F19: 2 | G19: =E19*F19 -> 1440
B20: Link | D20: 3对 | E20: 180 | F20: 3 | G20: =E20*F20 -> 540
B21: Link | C21: 受限使用Link磁粉探伤 | D21: 20件 | E21: 1200 | F21: 0 | G21: =E21*F21 -> 0
A22: TG | B22: TG | C22: 核对物料实物、随行单、看板，生产工单的信息一致 | D22: 1条履带 | E22: 60 | F22: 1 | G22: =E22*F22 -> 60 | H22: 1班1次
C23: 正在装配履带的第一节销孔直径验证 | D23: 1条履带 | E23: 60 | F23: 1 | G23: =E23*F23 -> 60 | H23: 1班1次
C24: 履带板倾斜度审核（目视） | D24: 1条履带 | E24: 30 | F24: 1 | G24: =E24*F24 -> 30 | H24: 1班1次
C25: 测量主销套凸出量。 | D25: 1条履带 | E25: 30 | F25: 1 | G25: =E25*F25 -> 30 | H25: 1班1次
C26: 测量开口量尺寸，并审核该处IPV标准化的执行。 | D26: 1次 | E26: 30 | F26: 1 | G26: =E26*F26 -> 30 | H26: 1班1次
C27: 履带节数的标准化执行确认审核 | D27: 1次 | E27: 30 | F27: 1 | G27: =E27*F27 -> 30 | H27: 1班1次
C28: 履带的边缘整齐度小于等于4mm | D28: 1条履带 | E28: 60 | F28: 1 | G28: =E28*F28 -> 60 | H28: 1班1次
C29: 履带的板缝≥2mm | D29: 1条履带 | E29: 30 | F29: 1 | G29: =E29*F29 -> 30 | H29: 1班1次
C30: 密封圈外径涂润滑油、销子销套装配面涂油 | D30: 1条履带 | E30: 30 | F30: 1 | G30: =E30*F30 -> 30 | H30: 1班1次
C31: 销套、销子突出量检查 | D31: 1条履带 | E31: 30 | F31: 1 | G31: =E31*F31 -> 30 | H31: 1班1次
C32: PPR履带压痕深度检查（如果适用） | D32: 1条履带 | E32: 30 | F32: 1 | G32: =E32*F32 -> 30 | H32: 1班1次
C33: 销子端面裂纹检查 | D33: 1条履带 | E33: 60 | F33: 1 | G33: =E33*F33 -> 60 | H33: 1班1次
C34: 主链接开口槽尺寸检查（如果适用） | D34: 1条履带 | E34: 30 | F34: 0.2 | G34: =E34*F34 -> 6 | H34: 1班1次
... C37: 有条形码的履带标签信息检查，与履带信息一致并完整 | D37: 1条履带 | E37: 30 | F37: 1 | G37: =E37*F37 -> 30 | H37: 1班1次
A38: Link-M | B38: Link机加工 | C38: Pin孔孔径 | D38: 1对 | E38: 30 | F38: 4 | G38: =E38*F38 -> 120 | H38: 2线2次，3线2次
C39: Bushing孔孔径 | D39: 1对 | E39: 30 | F39: 4 | G39: =E39*F39 -> 120 | H39: 2线2次，3线2次
C40: Pin孔与Bushing孔粗糙度 | D40: 1对 | E40: 240 | F40: 4 | G40: =E40*F40 -> 960 | H40: 2线2次，3线2次
C41: CMM报告 | D41: 1对 | E41: 30 | F41: 2 | G41: =E41*F41 -> 60 | H41: 2线1次，3线1次
C42: 外观检查 | D42: 4对 | E42: 120 | F42: 4 | G42: =E42*F42 -> 480 | H42: 2线2次，3线2次
...

Sheet 2025-4&5&轮线
A1: 区域 | B1: 零部件 | C1: 生产线工作内容 | D1: 数量 | E1: CT/秒 | F1: 频次/班 | G1: 用时/秒 | H1: 备注
A2: PBL-HT | B2: Pin | C2: 表硬 | D2: 1对 | E2: 120 | F2: 7 | G2: =E2*F2 -> 840 | H2: 4线4次，5线3次
B3: Bushing | C3: 表硬 | D3: 1对 | E3: 120 | F3: 7 | G3: =E3*F3 -> 840 | H3: 4线4次，5线3次
B4: Link | C4: H-length检测；表硬（开班） | D4: 1对 | E4: 480 | F4: 2 | G4: =E4*F4 -> 960 | H4: 4线1次，5线1次
B5: Link | C5: H-length检测；表硬（快速） | D5: 1对 | E5: 480 | F5: 4 | G5: =E5*F5 -> 1920 | H5: 4线3次，5线1次
B6: Pin（开班） | C6: 磁粉探伤 | D6: 1对 | E6: 60 | F6: 2 | G6: =E6*F6 -> 120 | H6: 4线1次，5线1次
B7: Pin（每2小时） | D7: 2对 | E7: 120 | F7: 6 | G7: =E7*F7 -> 720 | H7: 4线3次，5线3次
B8: Bushing（开班） | D8: 1对 | E8: 60 | F8: 2 | G8: =E8*F8 -> 120 | H8: 4线1次，5线1次
B9: Bushing（每2小时） | D9: 2对 | E9: 120 | F9: 6 | G9: =E9*F9 -> 720 | H9: 4线3次，5线3次
B10: Link（开班） | D10: 1对 | E10: 60 | F10: 2 | G10: =E10*F10 -> 120 | H10: 4线1次，5线1次
B11: Link（每2小时） | D11: 2对 | E11: 120 | F11: 6 | G11: =E11*F11 -> 720 | H11: 4线3次，5线3次
B12: Pin | C12: 热处理尺寸检测 | D12: 1对 | E12: 120 | F12: 5 | G12: =E12*F12 -> 600 | H12: 4线4次，5线1次
B13: Bushing | D13: 1对 | E13: 180 | F13: 4 | G13: =E13*F13 -> 720 | H13: 4线3次，5线1次
B14: Bushing（CMM） | D14: 1对 | E14: 720 | F14: 1 | G14: =E14*F14 -> 720 | H14: 4线1次
B15: Pin | C15: 外观目视检测 | D15: 10对 | E15: 100 | F15: 8 | G15: =E15*F15 -> 800 | H15: 销子销套链节各4线4次，5线4次
B16: Bushing | D16: 10对 | E16: 100 | F16: 8 | G16: =E16*F16 -> 800
B17: Link | D17: 6对 | E17: 150 | F17: 8 | G17: =E17*F17 -> 1200
B18: Link | C18: 换型打磨时间 | D18: 1对 | E18: 300 | F18: 2 | G18: =E18*F18 -> 600
B19: Pin | C19: 磁粉探伤（换型） | D19: 10对 | E19: 600 | F19: 1 | G19: =E19*F19 -> 600
B20: Bushing | D20: 12对 | E20: 720 | F20: 2 | G20: =E20*F20 -> 1440
B21: Link | D21: 3对 | E21: 180 | F21: 2 | G21: =E21*F21 -> 360
B22: Link | C22: 受限使用Link磁粉探伤 | D22: 20件 | E22: 1200 | F22: 0 | G22: =E22*F22 -> 0
A23: Link-M | B23: Link机加工 | C23: Pin孔孔径 | D23: 1对 | E23: 30 | F23: 4 | G23: =E23*F23 -> 120 | H23: 4线2次，5线2次
C24: Bushing孔孔径 | D24: 1对 | E24: 30 | F24: 4 | G24: =E24*F24 -> 120 | H24: 4线2次，5线2次
C25: Pin孔与Bushing孔粗糙度 | D25: 1对 | E25: 240 | F25: 4 | G25: =E25*F25 -> 960 | H25: 4线2次，5线2次
C26: CMM报告 | D26: 1对 | E26: 30 | F26: 2 | G26: =E26*F26 -> 60 | H26: 4线1次，5线1次
C27: 外观检查 | D27: 4对 | E27: 120 | F27: 4 | G27: =E27*F27 -> 480 | H27: 4线2次，5线2次
C28: 4线一轮CMM检测 | D28: 6对 | E28: 600 | F28: 1 | G28: =E28*F28 -> 600 | H28: 2线2次，3线2次
A29: TR | B29: TR | C29: CMT清洁度抽检 | D29: 1件 | E29: 300 | F29: 2 | G29: =E29*F29 -> 600 | H29: 白班1次，不合格无法估量次数
C30: 检查清洁度、目视清洁度检查 | D30: 4件 | E30: 500 | F30: 4 | G30: =E30*F30 -> 2000 | H30: 小轮线2次，大轮线2次
C31: 轮子沉孔方向朝上检查 | D31: 1件 | E31: 10 | F31: 4 | G31: =E31*F31 -> 40 | H31: 小轮线2次，大轮线2次
C32: 透盖处销子安装检查 | D32: 1件 | E32: 10 | F32: 4 | G32: =E32*F32 -> 40 | H32: 小轮线2次，大轮线2次
C33: 销子防窜印记检查 | D33: 2件 | E33: 10 | F33: 4 | G33: =E33*F33 -> 40 | H33: 小轮线2次，大轮线2次
C34: 漆膜厚度 | D34: 4件 | E34: 100 | F34: 4 | G34: =E34*F34 -> 400 | H34: 小轮线2次，大轮线2次
C35: 油漆质量 | D35: 1件 | E35: 60 | F35: 4 | G35: =E35*F35 -> 240 | H35: 小轮线2次，大轮线2次
C36: 打销印记检查（装配工位与成品工位）丝堵高度检查（小于等于1.5mm) | D36: 1件 | E36: 30 | F36: 4 | G36: =E36*F36 -> 120 | H36: 小轮线2次，大轮线2次
A37: 其它 | B37: PB | C37: 待处理物料审核 | E37: 300 | F37: 4 | G37: =E37*F37 -> 1200 | H37: 4线4次，5线4次
B38: Link | C38: 待处理物料审核 | E38: 300 | F38: 4 | G38: =E38*F38 -> 1200 | H38: 4线4次，5线4次
B39: SWS审核 | C39: OP /SC-SWS审核 | E39: 1800 | F39: 1 | G39: =E39*F39 -> 1800
B40: 系统更新 | C40: BIQ系统更新、返工单录入等 | E40: 600 | F40: 1 | G40: =E40*F40 -> 600
...

Sheet Sheet1
A1: L2&L3线统计（S）
A2: 状态 | B2: 类型 | C2: L1&L2&L3&轮线时间统计 | D2: L4&L5时间统计
A3: 静态 | B3: P/B/L表硬&H length | C3: 3000 | D3: 2700
B4: P/B/L MT | C4: 1440 | D4: 1260
B5: P/B尺寸检测 | C5: 2040 | D5: 2040
B6: P/B/L 工艺送检&月度检测 | C6: 2100 | D6: 2100
A7: 动态 | B7: P/B/L外观目视 | C7: 2800 | D7: 2800
A8: 静态 | B8: P/B/Link换型（MT&H-T&工艺&尺寸） | C8: 1080 | D8: 1080
B9: P/B换型（MT） | C9: 1860 | D9: 1860
A10: 静态 | B10: 换炉号(MT&硬度&工艺&尺寸） | C10: 1080 | D10: 1080
A11: 静态 | B11: 履带装配审核 | C11: 2560 | D11: 2560
B12: 机加工审核 | C12: 1800 | D12: 1800
B13: 支重轮审核 | C13: 1672
A14: 动态 | B14: PB发货件加严检测 | C14: 844 | D14: 844
A15: 其他审核 | B15: 待处理物料审核 | C15: 300 | D15: 300
B16: 待处理物料审核 | C16: 300 | D16: 300
B17: OP /SC-SWS审核 | C17: 1800 | D17: 1800
B18: BIQ系统更新、返工单录入等 | C18: 600 | D18: 600
B19: 现场检验行走时间 | C19: 1800 | D19: 1800
B20: 在线返工物料检测 | C20: 1080 | D20: 1080
B21: 现场质量问题处理 | C21: 2400 | D21: 2400
B22: 毒蘑菇实验 | C22: 297 | D22: 297
B23: 5线压痕检测 | C23: 120 | D23: 120
B25: (S) | C25: =SUM(C3:C23) -> 30973 | D25: =SUM(D3:D23) -> 28821
B26: (min) | C26: =C25/60 -> 516.21667 | D26: =D25/60 -> 480.35

Sheet 20200227
A1: 区域 | B1: 零部件 | C1: 动静态 | D1: 单条生产线工作内容 | E1: CT/秒 | F1: 频次/班 | G1: 轮、2、3线白班、夜班用时/min | H1: 涂漆、4、5线白班、夜班用时/min | I1: 中班用时/min | K1: 项目 | L1: 分钟
A2: PBL-HT | B2: PBL | C2: 静态&动态必查项 | E2: =SUM(H14:H27) -> 4700 | F2: 2 | G2: =E2*F2/60 -> 156.66667 | H2: =E2*F2/60 -> 156.66667 | I2: =E2*F2/60*2-1080/60-(720*4-360)/60 -> 253.33333 | K2: 总工时 | L2: 480
C3: 动态选查项 | E3: =SUM(H28:H35) -> 3890 | F3: 2 | G3: =E3*F3/60 -> 129.66667 | H3: =E3*F3/60 -> 129.66667 | K3: 班会 | L3: 15
A4: TG | B4: TG | C4: 动态必查项 | E4: =SUM(H43:H58) -> 853.33333 | F4: =1/2 -> 0.5 | G4: =E4*F4/60 -> 7.1111111 | H4: =E4*F4/60 -> 7.1111111 | I4: =E4*F4/60 -> 7.1111111 | K4: OPM | L4: 10
A5: TG | B5: TG | C5: 动态选查项 | E5: =SUM(H59:H61) -> 133.33333 | F5: =1/2 -> 0.5 | G5: =E5*F5/60 -> 1.1111111 | H5: =E5*F5/60 -> 1.1111111 | K5: 吃饭 | L5: 20
A6: Link-M | B6: Link-M | C6: 动态必查项 | E6: =SUM(H62:H63) -> 850 | F6: 1 | G6: =E6*F6/60 -> 14.166667 | H6: =(E6-500)*F6/60 -> 5.8333333 | I6: =E6*F6/60 -> 14.166667 | K6: 工作时间 | L6: =L2-L3-L4-L5 -> 435 | M6: 0.88
A7: TR | B7: TR | C7: 动态必查项 | E7: =SUM(H64:H81) -> 2209.3333 | F7: =1/2 -> 0.5 | G7: =E7*F7/60 -> 18.411111 | H7: 0 | I7: =(E7-H64)*F7/60 -> 5.9111111 | K7: OEE时间 | L7: =L6*0.88 -> 382.8
C8: 动态选查项 | E8: =SUM(H82) -> 24 | F8: =1/2 -> 0.5 | G8: =E8*F8/60 -> 0.2 | H8: 0
A9: 其他 | B9: 其他 | E9: =SUM(H36:H42) -> 5800 | F9: 1 | G9: =E9*F9/60 -> 96.666667 | H9: =E9*F9/60 -> 96.666667 | I9: =E9*F9/60*2-30 -> 163.33333
A10: Total | G10: =SUM(G2:G9) -> 424 | H10: =SUM(H2:H9) -> 397.05556 | I10: =SUM(I2:I9) -> 443.85556
A11: 必查项汇总 | G11: =G2+G4+G6+G7+G9 -> 293.02222 | H11: =H2+H4+H6+H7+H9 -> 266.27778 | I11: =I2+I4+I6+I7+I9 -> 443.85556
A12: 选查项汇总 | G12: =G3+G5+G8 -> 130.97778 | H12: =H3+H5+H8 -> 130.77778 | I12: =I3+I5+I8 -> 0
A13: 区域 | B13: 零部件 | C13: 动静态 | D13: 单条生产线工作内容 | E13: 数量 | F13: CT/秒 | G13: 频次/班 | H13: 用时/秒
A14: PBL-HT | B14: Pin | C14: 静态 | D14: 表硬与H-length检测 | E14: 1对 | F14: 120 | G14: 2 | H14: =F14*G14 -> 240
B15: Bushing | E15: 1对 | F15: 120 | G15: 2 | H15: =F15*G15 -> 240
B16: Link | E16: 1对 | F16: 300 | G16: 2 | H16: =F16*G16 -> 600
B17: Pin | D17: 磁粉探伤 | E17: 1对 | F17: 60 | G17: 4 | H17: =F17*G17 -> 240
B18: Bushing | E18: 1对 | F18: 60 | G18: 4 | H18: =F18*G18 -> 240
B19: Link | E19: 1对 | F19: 60 | G19: 4 | H19: =F19*G19 -> 240
B20: PBL | D20: 工艺送检 | E20: 3对 | F20: 600 | G20: 1 | H20: =F20*G20 -> 600
B21: Pin | D21: 月度检查项 | E21: 1对 | F21: 1320 | G21: 0.2 | H21: =F21*G21 -> 264
B22: Bushing | D22: 月度检查项 | E22: 1对 | F22: 1680 | G22: 0.2 | H22: =F22*G22 -> 336
B23: Pin | C23: 动态必查项 | D23: 热处理尺寸检测 | E23: 1对 | F23: 120 | G23: 1 | H23: =F23*G23 -> 120
B24: Bushing | E24: 1对 | F24: 180 | G24: 1 | H24: =F24*G24 -> 180
B25: Pin | D25: 外观目视检测 | E25: 6对 | F25: 100 | G25: 4 | H25: =F25*G25 -> 400
B26: Bushing | E26: 6对 | F26: 100 | G26: 4 | H26: =F26*G26 -> 400
B27: Link | E27: 6对 | F27: 150 | G27: 4 | H27: =F27*G27 -> 600
B28: Bushing | C28: 动态选查项 | D28: 加严磁粉探伤 | E28: 2对 | F28: 100 | G28: 4 | H28: =F28*G28 -> 400
B29: Bushing | E29: 3对 | F29: 150 | G29: 3 | H29: =F29*G29 -> 450
B30: Link | E30: 2对 | F30: 140 | G30: 3 | H30: =F30*G30 -> 420
B31: Pin（手检与上合并） | D31: 发货物料加严尺寸检测 | E31: 3对 | F31: 360 | G31: 1 | H31: =F31*G31 -> 360
B32: Pin（CMM） | E32: 4对 | F32: 600 | G32: 1 | H32: =F32*G32 -> 600
B33: Bushing | E33: 3对 | F33: 540 | G33: 1 | H33: =F33*G33 -> 540
B34: Bushing（CMM） | E34: 4对 | F34: 720 | G34: 1 | H34: =F34*G34 -> 720
B35: Link | D35: 换模具号磁粉探伤 | E35: 20件 | F35: 800 | G35: 0.5 | H35: =F35*G35 -> 400
A36: 其他 | B36: Link | D36: 换型后H-length检测记录并送检工艺、换型物料磁粉探伤 | E36: 6件 | F36: 1100 | G36: 1 | H36: =F36*G36 -> 1100
B37: PB | D37: 待处理物料审核 | F37: 300 | G37: 1 | H37: =F37*G37 -> 300
B38: Link | D38: 待处理物料审核 | F38: 300 | G38: 1 | H38: =F38*G38 -> 300
B39: SWS审核 | D39: OP /SC-SWS审核 | F39: 1800 | G39: 1 | H39: =F39*G39 -> 1800
B40: 系统更新 | D40: BIQ系统更新、返工单录入等 | F40: 600 | G40: 1 | H40: =F40*G40 -> 600
...

Sheet QG 20171011-Line345
A1: QG工作内容时间表
A2: 工作内容 | B2: 区域 | C2: 零部件 | D2: 单条生产线工作内容 | E2: CT | F2: 频率 | G2: 白班每天所需时间 | H2: 夜班每天所需时间 | I2: 实际时间 | J2: 小时
A3: / | B3: 合计 | E3: =SUM(E4:E8) -> 340.5 | J3: =E3/60 -> 5.675
B4: PB-HT | E4: =SUM(G9:G10,G12:G13,G15:G19,G21:G22,G24:G25,G27:G28) -> 123 | J4: =E4/60 -> 2.05
B5: Link-H | E5: =SUM(G11,G14,G20,G23,G26,G29) -> 45.5 | J5: =E5/60 -> 0.75833333
B6: Link-M | E6: =SUM(G30:G31) -> 10 | J6: =E6/60 -> 0.16666667
B7: ASS | E7: =SUM(G32:G34) -> 80 | J7: =E7/60 -> 1.3333333
B8: Roller | E8: =SUM(G35:G41) -> 82 | J8: =E8/60 -> 1.3666667
A9: 开班 | B9: PBL热处理 | C9: Pin | D9: 开班检测Pin2pcs | E9: 10 | F9: 1 | G9: =F9*E9 -> 10 | H9: =E9*1 -> 10
C10: Bushing | D10: 开班检测Bushing2pcs | E10: 10 | F10: 1 | G10: =F10*E10 -> 10 | H10: =E10*1 -> 10
C11: Link | D11: 开班检测Link2pcs | E11: 10 | F11: 1 | G11: =F11*E11 -> 10 | H11: =E11*1 -> 10
A12: 工艺 | C12: Pin | D12: 工艺送检Pin2pcs | E12: 5 | F12: 1 | G12: =F12*E12 -> 5 | H12: =E12*2 -> 10
C13: Bushing | D13: 工艺送检Bushing2pcs | E13: 5 | F13: 1 | G13: =F13*E13 -> 5 | H13: =E13*2 -> 10
C14: Link | D14: 工艺送检Link2pcs | E14: 5 | F14: 1 | G14: =F14*E14 -> 5 | H14: =E14*1 -> 5
A15: 序间检测 | C15: Pin | D15: Pin的热处理尺寸检测/2pcs | E15: 2 | F15: 2 | G15: =F15*E15 -> 4 | H15: =E15*2 -> 4
C16: Pin | D16: Pin的毛坯尺寸检测/2pcs
C17: Bushing | D17: Bushing的热处理尺寸检测/2pcs | E17: 12 | F17: 2 | G17: =F17*E17 -> 24 | H17: =E17*2 -> 24
C18: Pin | D18: Pin的外观检测/6pcs | E18: 3 | F18: 2 | G18: =F18*E18 -> 6 | H18: =E18*6 -> 18
C19: Bushing | D19: Bushing的外观检测/6pcs | E19: 3 | F19: 2 | G19: =F19*E19 -> 6 | H19: =E19*2 -> 6
C20: Link | D20: Link的外观检测/4pcs | E20: 2 | F20: 2 | G20: =F20*E20 -> 4 | H20: =E20*3 -> 6
C21: Pin | D21: 磁粉探伤/2pcs | E21: 1.5 | F21: 3 | G21: =F21*E21 -> 4.5 | H21: =E21*3 -> 4.5
C22: Bushing | D22: 磁粉探伤/2pcs | E22: 1.5 | F22: 3 | G22: =F22*E22 -> 4.5 | H22: =E22*3 -> 4.5
C23: Link | D23: 磁粉探伤/2pcs | E23: 1.5 | F23: 3 | G23: =F23*E23 -> 4.5 | H23: =E23*3 -> 4.5
C24: Pin | D24: 表硬检测/2pcs | E24: 4 | F24: 3 | G24: =F24*E24 -> 12 | H24: =E24*3 -> 12
C25: Bushing | D25: 表硬检测/2pcs | E25: 4 | F25: 3 | G25: =F25*E25 -> 12 | H25: =E25*3 -> 12
C26: Link | D26: 表硬检测/2pcs | E26: 4 | F26: 3 | G26: =F26*E26 -> 12 | H26: =E26*3 -> 12
A27: 序间巡检 | C27: Pin-HT | D27: 待处理物料审核 | E27: 10 | F27: 1 | G27: =F27*E27 -> 10 | H27: =E27*1 -> 10
C28: Bushing-HT | D28: 待处理物料审核 | E28: 10 | F28: 1 | G28: =F28*E28 -> 10 | H28: =E28*1 -> 10
C29: Link-HT | D29: 待处理物料审核 | E29: 10 | F29: 1 | G29: =F29*E29 -> 10 | H29: =E29*1 -> 10
B30: Link-M | C30: Link-M | D30: 待处理物料审核 | E30: 10 | F30: 1 | G30: =F30*E30 -> 10 | H30: =E30*1 -> 10
D31: 机加工粗糙度检测 | E31: 10 | F31: 0 | G31: =F31*E31 -> 0 | H31: =E31*1 -> 10
B32: ASS | C32: ASS | D32: 待处理物料审核 | E32: 10 | F32: 1 | G32: =F32*E32 -> 10 | H32: =E32*1 -> 10
C33: ASS | D33: 开口/整齐度/板缝 | E33: 2 | F33: 10 | G33: =F33*E33 -> 20 | H33: =E33*10 -> 20
C34: ASS | D34: 外观检测 | E34: 5 | F34: 10 | G34: =F34*E34 -> 50 | H34: =E34*10 -> 50
A35: 序间检测 | B35: Roller | C35: Roller | D35: 清洁度送检 | E35: 5 | F35: 2 | G35: =F35*E35 -> 10
C36: Roller | D36: 密封圈高度 | E36: 1 | F36: 2 | G36: =F36*E36 -> 2
C37: Roller | D37: 轴承跨距 | E37: 2.5 | F37: 2 | G37: =F37*E37 -> 5
C38: Roller | D38: 窜动量 | E38: 2.5 | F38: 2 | G38: =F38*E38 -> 5
C39: Roller | D39: 零部件检测 | E39: 10 | F39: 2 | G39: =F39*E39 -> 20
A40: 序间巡检 | C40: Roller | D40: 待处理物料审核 | E40: 10 | F40: 1 | G40: =F40*E40 -> 10
...
